
  0%|          | 0/10291 [00:00<?, ?it/s]C:\Users\CYP\AppData\Local\Temp\ipykernel_45920\3389204729.py:40: UserWarning: Using a target size (torch.Size([64, 64])) that is different to the input size (torch.Size([64])). This will likely lead to incorrect results due to broadcasting. Please ensure they have the same size.
  elif loss_type == "smooth_l1":loss = F.smooth_l1_loss(q_pred, bellman_target)



  4%|▍         | 411/10291 [00:12<05:09, 31.88it/s]
[W 2024-03-19 12:42:49,286] Trial 0 failed with parameters: {'batch_size': 64, 'n_units': 2, 'learning_rate': 1e-05, 'lr_decay': 0.75, 'lr_step': 5, 'negative_sampling': 4, 'loss': 'smooth_l1', 'update_freq': 8} because of the following error: KeyboardInterrupt().
Traceback (most recent call last):
  File "c:\Users\CYP\anaconda3\envs\torch\lib\site-packages\optuna\study\_optimize.py", line 200, in _run_trial
    value_or_values = func(trial)
  File "C:\Users\CYP\AppData\Local\Temp\ipykernel_45920\339626687.py", line 29, in objective
    auroc = train(batch_size,n_units,lr,lr_decay,lr_step,ns,loss,epochs,update_freq)
  File "C:\Users\CYP\AppData\Local\Temp\ipykernel_45920\3389204729.py", line 33, in train
    q2,_,_ = target_network(s2)
  File "c:\Users\CYP\anaconda3\envs\torch\lib\site-packages\torch\nn\modules\module.py", line 1511, in _wrapped_call_impl
    return self._call_impl(*args, **kwargs)
  File "c:\Users\CYP\anaconda3\envs\torch\lib\site-packages\torch\nn\modules\module.py", line 1520, in _call_impl
    return forward_call(*args, **kwargs)
KeyboardInterrupt
[W 2024-03-19 12:42:49,288] Trial 0 failed with value None.
[I 2024-03-19 12:42:52,652] A new study created in memory with name: no-name-099c7d03-b6c2-4058-a578-6ad83cca1e4c