
  0%|          | 0/20583 [00:00<?, ?it/s]C:\Users\CYP\AppData\Local\Temp\ipykernel_75780\757422201.py:40: UserWarning: Using a target size (torch.Size([32, 32])) that is different to the input size (torch.Size([32])). This will likely lead to incorrect results due to broadcasting. Please ensure they have the same size.
  elif loss_type == "mse":loss = F.mse_loss(q_pred, bellman_target)















































































































21235it [03:48, 93.04it/s]
C:\Users\CYP\AppData\Local\Temp\ipykernel_75780\757422201.py:73: UserWarning: Using a target size (torch.Size([256, 256])) that is different to the input size (torch.Size([256])). This will likely lead to incorrect results due to broadcasting. Please ensure they have the same size.
  elif loss_type == "mse":loss = F.mse_loss(q_pred, bellman_target)
C:\Users\CYP\AppData\Local\Temp\ipykernel_75780\757422201.py:73: UserWarning: Using a target size (torch.Size([77, 77])) that is different to the input size (torch.Size([77])). This will likely lead to incorrect results due to broadcasting. Please ensure they have the same size.
  elif loss_type == "mse":loss = F.mse_loss(q_pred, bellman_target)
  0%|          | 0/20583 [00:00<?, ?it/s]C:\Users\CYP\AppData\Local\Temp\ipykernel_75780\757422201.py:40: UserWarning: Using a target size (torch.Size([32, 32])) that is different to the input size (torch.Size([32])). This will likely lead to incorrect results due to broadcasting. Please ensure they have the same size.
  elif loss_type == "mse":loss = F.mse_loss(q_pred, bellman_target)










































































































 99%|█████████▉| 20372/20583 [03:36<00:02, 93.96it/s]
[W 2024-03-20 17:44:28,622] Trial 15 failed with parameters: {'batch_size': 32, 'n_units': 64, 'learning_rate': 0.0001, 'lr_decay': 0.8, 'lr_step': 10, 'negative_sampling': 2, 'loss': 'mse', 'update_freq': 32} because of the following error: KeyboardInterrupt().
Traceback (most recent call last):
  File "c:\Users\CYP\anaconda3\envs\torch\lib\site-packages\optuna\study\_optimize.py", line 200, in _run_trial
    value_or_values = func(trial)
  File "C:\Users\CYP\AppData\Local\Temp\ipykernel_75780\961001870.py", line 29, in objective
    auroc = train(batch_size,n_units,lr,lr_decay,lr_step,ns,loss,epochs,update_freq)
  File "C:\Users\CYP\AppData\Local\Temp\ipykernel_75780\757422201.py", line 33, in train
    q2_net,_,_ = network(s2)
  File "c:\Users\CYP\anaconda3\envs\torch\lib\site-packages\torch\nn\modules\module.py", line 1511, in _wrapped_call_impl
    return self._call_impl(*args, **kwargs)
  File "c:\Users\CYP\anaconda3\envs\torch\lib\site-packages\torch\nn\modules\module.py", line 1520, in _call_impl
    return forward_call(*args, **kwargs)
KeyboardInterrupt
[W 2024-03-20 17:44:28,624] Trial 15 failed with value None.
[I 2024-03-20 17:44:56,937] A new study created in memory with name: no-name-c7d65d17-43b0-447f-b412-0a110b64015a